Workbook

Sheet Raw Dataset
A1: CIF | B1: Cust_Name | C1: Usia | D1: Jenis Kelamin | E1: Date_Cif_Open | F1: Acc_Number | G1: Date_Acc_Open | H1: Product_Code | I1: Balance | J1: Avg_Balance | K1: SND
A2: 2287021 | B2: Budi Kusuma | C2: 35 | D2: Perempuan | E2: 44337 | F2: 445036 | G2: 44347 | H2: 621 | I2: 2348116 | J2: 8955367 | K2: SND01
A3: 3684345 | B3: Wulan Wibowo | C3: 29 | D3: Laki-laki | E3: 45782 | F3: 690376 | G3: 45792 | H3: 620 | I3: 4632122 | J3: 6250736 | K3: SND02
A4: 6507231 | B4: Yudi Santoso | C4: 37 | D4: Perempuan | E4: 44761 | F4: 726795 | G4: 44771 | H4: 521 | I4: 4676007 | J4: 6844373 | K4: SND03
A5: 2306909 | B5: Hendra Permana | C5: 25 | D5: Perempuan | E5: 45643 | F5: 471359 | G5: 45653 | H5: 808 | I5: 5717876 | J5: 8325624 | K5: SND04
A6: 6713678 | B6: Rina Rahayu | C6: 29 | D6: Perempuan | E6: 44631 | F6: 222391 | G6: 44641 | H6: 413 | I6: 2158895 | J6: 8347943 | K6: SND05
A7: 3477250 | B7: Lina Wibowo | C7: 45 | D7: Perempuan | E7: 44992 | F7: 784959 | G7: 45002 | H7: 712 | I7: 2203171 | J7: 5618396 | K7: SND06
A8: 2446706 | B8: Joko Sari | C8: 55 | D8: Perempuan | E8: 44196 | F8: 670347 | G8: 44206 | H8: 621 | I8: 3722178 | J8: 6563564 | K8: SND07
A9: 8882904 | B9: Hadi Saputri | C9: 20 | D9: Perempuan | E9: 44554 | F9: 992697 | G9: 44564 | H9: 620 | I9: 2173515 | J9: 5182322 | K9: SND08
A10: 2985075 | B10: Kartika Kurniawan | C10: 64 | D10: Perempuan | E10: 45077 | F10: 855807 | G10: 45087 | H10: 521 | I10: 5867720 | J10: 7688655 | K10: SND09
A11: 3365113 | B11: Indah Ramadhan | C11: 31 | D11: Perempuan | E11: 43874 | F11: 782420 | G11: 43884 | H11: 808 | I11: 7629989 | J11: 6784112 | K11: SND10
A12: 8369052 | B12: Dewi Nugroho | C12: 28 | D12: Laki-laki | E12: 44883 | F12: 800474 | G12: 44893 | H12: 413 | I12: 18287346 | J12: 20678701 | K12: SND11
A13: 2918715 | B13: Joko Putra | C13: 47 | D13: Laki-laki | E13: 45068 | F13: 607697 | G13: 45078 | H13: 712 | I13: 6355438 | J13: 11137340 | K13: SND12
... A135: 5113873 | B135: Putri Kusuma | C135: 22 | D135: Perempuan | E135: 45700 | F135: 383843 | G135: 45710 | H135: 620 | I135: 14876013 | J135: 5558765 | K135: SND04

Sheet Data Processing
A1: CIF | B1: Cust_Name | C1: Usia | D1: Jenis Kelamin | E1: Date_Cif_Open | F1: Acc_Number | G1: Date_Acc_Open | H1: Product_Code | I1: Balance | J1: Avg_Balance | K1: SND | L1: Region | M1: Product Name | N1: Cust Segmen | O1: Cust Profiling | P1: Flag
A2: 2287021 | B2: =TRIM('Raw Dataset'!B2) -> Budi Kusuma | C2: 35 | D2: Perempuan | E2: 44337 | F2: 445036 | G2: 44347 | H2: 621 | I2: 2348116 | J2: 8955367 | K2: SND01 | L2: =_xlfn.XLOOKUP(K2,Lookup!$G$4:$G$15,Lookup!$F$4:$F$15,"Unmapping",0,1) -> Jawa Barat | M2: =VLOOKUP(H2,Lookup!$C$4:$D$9,2,0) -> Tab Hajj | N2: =IF(I2<10000000,"Mass Market",IF(I2<=50000000,"Optimal","Privilage")) -> Mass Market | O2: {=_xlfn.IFS(C2<=25,"Grade C",C2<=35,"Grade A",C2<=55,"Grade B",C2>55,"Grade D")} -> Grade A | P2: =INDEX($T$13:$W$15,MATCH(N2,$S$13:$S$15,0),MATCH(O2,$T$12:$W$12,0)) -> Low
A3: 3684345 | B3: =TRIM('Raw Dataset'!B3) -> Wulan Wibowo | C3: 29 | D3: Laki-laki | E3: 45782 | F3: 690376 | G3: 45792 | H3: 620 | I3: 4632122 | J3: 6250736 | K3: SND02 | L3: =_xlfn.XLOOKUP(K3,Lookup!$G$4:$G$15,Lookup!$F$4:$F$15,"Unmapping",0,1) -> Sumatera Selatan | M3: =VLOOKUP(H3,Lookup!$C$4:$D$9,2,0) -> Wadiah | N3: =IF(I3<10000000,"Mass Market",IF(I3<=50000000,"Optimal","Privilage")) -> Mass Market | O3: {=_xlfn.IFS(C3<=25,"Grade C",C3<=35,"Grade A",C3<=55,"Grade B",C3>55,"Grade D")} -> Grade A | P3: =INDEX($T$13:$W$15,MATCH(N3,$S$13:$S$15,0),MATCH(O3,$T$12:$W$12,0)) -> Low
A4: 6507231 | B4: =TRIM('Raw Dataset'!B4) -> Yudi Santoso | C4: 37 | D4: Perempuan | E4: 44761 | F4: 726795 | G4: 44771 | H4: 521 | I4: 4676007 | J4: 6844373 | K4: SND03 | L4: =_xlfn.XLOOKUP(K4,Lookup!$G$4:$G$15,Lookup!$F$4:$F$15,"Unmapping",0,1) -> Jawa Tengah | M4: =VLOOKUP(H4,Lookup!$C$4:$D$9,2,0) -> Special Hajj | N4: =IF(I4<10000000,"Mass Market",IF(I4<=50000000,"Optimal","Privilage")) -> Mass Market | O4: {=_xlfn.IFS(C4<=25,"Grade C",C4<=35,"Grade A",C4<=55,"Grade B",C4>55,"Grade D")} -> Grade B | P4: =INDEX($T$13:$W$15,MATCH(N4,$S$13:$S$15,0),MATCH(O4,$T$12:$W$12,0)) -> Low | S4: Tier | T4: Usia
A5: 2306909 | B5: =TRIM('Raw Dataset'!B5) -> Hendra Permana | C5: 25 | D5: Perempuan | E5: 45643 | F5: 471359 | G5: 45653 | H5: 808 | I5: 5717876 | J5: 8325624 | K5: SND04 | L5: =_xlfn.XLOOKUP(K5,Lookup!$G$4:$G$15,Lookup!$F$4:$F$15,"Unmapping",0,1) -> Jawa Timur | M5: =VLOOKUP(H5,Lookup!$C$4:$D$9,2,0) -> Tab Umroh | N5: =IF(I5<10000000,"Mass Market",IF(I5<=50000000,"Optimal","Privilage")) -> Mass Market | O5: {=_xlfn.IFS(C5<=25,"Grade C",C5<=35,"Grade A",C5<=55,"Grade B",C5>55,"Grade D")} -> Grade C | P5: =INDEX($T$13:$W$15,MATCH(N5,$S$13:$S$15,0),MATCH(O5,$T$12:$W$12,0)) -> Low | S5: Grade A | T5: 25-35
A6: 6713678 | B6: =TRIM('Raw Dataset'!B6) -> Rina Rahayu | C6: 29 | D6: Perempuan | E6: 44631 | F6: 222391 | G6: 44641 | H6: 413 | I6: 2158895 | J6: 8347943 | K6: SND05 | L6: =_xlfn.XLOOKUP(K6,Lookup!$G$4:$G$15,Lookup!$F$4:$F$15,"Unmapping",0,1) -> Kalimantan | M6: =VLOOKUP(H6,Lookup!$C$4:$D$9,2,0) -> Tab Valas | N6: =IF(I6<10000000,"Mass Market",IF(I6<=50000000,"Optimal","Privilage")) -> Mass Market | O6: {=_xlfn.IFS(C6<=25,"Grade C",C6<=35,"Grade A",C6<=55,"Grade B",C6>55,"Grade D")} -> Grade A | P6: =INDEX($T$13:$W$15,MATCH(N6,$S$13:$S$15,0),MATCH(O6,$T$12:$W$12,0)) -> Low | S6: Grade B | T6: 35-55
A7: 3477250 | B7: =TRIM('Raw Dataset'!B7) -> Lina Wibowo | C7: 45 | D7: Perempuan | E7: 44992 | F7: 784959 | G7: 45002 | H7: 712 | I7: 2203171 | J7: 5618396 | K7: SND06 | L7: =_xlfn.XLOOKUP(K7,Lookup!$G$4:$G$15,Lookup!$F$4:$F$15,"Unmapping",0,1) -> Sumatera Utara | M7: =VLOOKUP(H7,Lookup!$C$4:$D$9,2,0) -> Tab Syariah | N7: =IF(I7<10000000,"Mass Market",IF(I7<=50000000,"Optimal","Privilage")) -> Mass Market | O7: {=_xlfn.IFS(C7<=25,"Grade C",C7<=35,"Grade A",C7<=55,"Grade B",C7>55,"Grade D")} -> Grade B | P7: =INDEX($T$13:$W$15,MATCH(N7,$S$13:$S$15,0),MATCH(O7,$T$12:$W$12,0)) -> Low | S7: Grade C | T7: < 25
A8: 2446706 | B8: =TRIM('Raw Dataset'!B8) -> Joko Sari | C8: 55 | D8: Perempuan | E8: 44196 | F8: 670347 | G8: 44206 | H8: 621 | I8: 3722178 | J8: 6563564 | K8: SND07 | L8: =_xlfn.XLOOKUP(K8,Lookup!$G$4:$G$15,Lookup!$F$4:$F$15,"Unmapping",0,1) -> DKI Jakarta | M8: =VLOOKUP(H8,Lookup!$C$4:$D$9,2,0) -> Tab Hajj | N8: =IF(I8<10000000,"Mass Market",IF(I8<=50000000,"Optimal","Privilage")) -> Mass Market | O8: {=_xlfn.IFS(C8<=25,"Grade C",C8<=35,"Grade A",C8<=55,"Grade B",C8>55,"Grade D")} -> Grade B | P8: =INDEX($T$13:$W$15,MATCH(N8,$S$13:$S$15,0),MATCH(O8,$T$12:$W$12,0)) -> Low | S8: Grade D | T8: > 55
A9: 8882904 | B9: =TRIM('Raw Dataset'!B9) -> Hadi Saputri | C9: 20 | D9: Perempuan | E9: 44554 | F9: 992697 | G9: 44564 | H9: 620 | I9: 2173515 | J9: 5182322 | K9: SND08 | L9: =_xlfn.XLOOKUP(K9,Lookup!$G$4:$G$15,Lookup!$F$4:$F$15,"Unmapping",0,1) -> Papua | M9: =VLOOKUP(H9,Lookup!$C$4:$D$9,2,0) -> Wadiah | N9: =IF(I9<10000000,"Mass Market",IF(I9<=50000000,"Optimal","Privilage")) -> Mass Market | O9: {=_xlfn.IFS(C9<=25,"Grade C",C9<=35,"Grade A",C9<=55,"Grade B",C9>55,"Grade D")} -> Grade C | P9: =INDEX($T$13:$W$15,MATCH(N9,$S$13:$S$15,0),MATCH(O9,$T$12:$W$12,0)) -> Low
A10: 2985075 | B10: =TRIM('Raw Dataset'!B10) -> Kartika Kurniawan | C10: 64 | D10: Perempuan | E10: 45077 | F10: 855807 | G10: 45087 | H10: 521 | I10: 5867720 | J10: 7688655 | K10: SND09 | L10: =_xlfn.XLOOKUP(K10,Lookup!$G$4:$G$15,Lookup!$F$4:$F$15,"Unmapping",0,1) -> Bali | M10: =VLOOKUP(H10,Lookup!$C$4:$D$9,2,0) -> Special Hajj | N10: =IF(I10<10000000,"Mass Market",IF(I10<=50000000,"Optimal","Privilage")) -> Mass Market | O10: {=_xlfn.IFS(C10<=25,"Grade C",C10<=35,"Grade A",C10<=55,"Grade B",C10>55,"Grade D")} -> Grade D | P10: =INDEX($T$13:$W$15,MATCH(N10,$S$13:$S$15,0),MATCH(O10,$T$12:$W$12,0)) -> Low
A11: 3365113 | B11: =TRIM('Raw Dataset'!B11) -> Indah Ramadhan | C11: 31 | D11: Perempuan | E11: 43874 | F11: 782420 | G11: 43884 | H11: 808 | I11: 7629989 | J11: 6784112 | K11: SND10 | L11: =_xlfn.XLOOKUP(K11,Lookup!$G$4:$G$15,Lookup!$F$4:$F$15,"Unmapping",0,1) -> Maluku | M11: =VLOOKUP(H11,Lookup!$C$4:$D$9,2,0) -> Tab Umroh | N11: =IF(I11<10000000,"Mass Market",IF(I11<=50000000,"Optimal","Privilage")) -> Mass Market | O11: {=_xlfn.IFS(C11<=25,"Grade C",C11<=35,"Grade A",C11<=55,"Grade B",C11>55,"Grade D")} -> Grade A | P11: =INDEX($T$13:$W$15,MATCH(N11,$S$13:$S$15,0),MATCH(O11,$T$12:$W$12,0)) -> Low | S11: Cust Segmen | T11: Tier Prioritas
A12: 8369052 | B12: =TRIM('Raw Dataset'!B12) -> Dewi Nugroho | C12: 28 | D12: Laki-laki | E12: 44883 | F12: 800474 | G12: 44893 | H12: 413 | I12: 18287346 | J12: 20678701 | K12: SND11 | L12: =_xlfn.XLOOKUP(K12,Lookup!$G$4:$G$15,Lookup!$F$4:$F$15,"Unmapping",0,1) -> Sulawesi Utara | M12: =VLOOKUP(H12,Lookup!$C$4:$D$9,2,0) -> Tab Valas | N12: =IF(I12<10000000,"Mass Market",IF(I12<=50000000,"Optimal","Privilage")) -> Optimal | O12: {=_xlfn.IFS(C12<=25,"Grade C",C12<=35,"Grade A",C12<=55,"Grade B",C12>55,"Grade D")} -> Grade A | P12: =INDEX($T$13:$W$15,MATCH(N12,$S$13:$S$15,0),MATCH(O12,$T$12:$W$12,0)) -> High | T12: Grade A | U12: Grade B | V12: Grade C | W12: Grade D
A13: 2918715 | B13: =TRIM('Raw Dataset'!B13) -> Joko Putra | C13: 47 | D13: Laki-laki | E13: 45068 | F13: 607697 | G13: 45078 | H13: 712 | I13: 6355438 | J13: 11137340 | K13: SND12 | L13: =_xlfn.XLOOKUP(K13,Lookup!$G$4:$G$15,Lookup!$F$4:$F$15,"Unmapping",0,1) -> Sulawesi Tenggara | M13: =VLOOKUP(H13,Lookup!$C$4:$D$9,2,0) -> Tab Syariah | N13: =IF(I13<10000000,"Mass Market",IF(I13<=50000000,"Optimal","Privilage")) -> Mass Market | O13: {=_xlfn.IFS(C13<=25,"Grade C",C13<=35,"Grade A",C13<=55,"Grade B",C13>55,"Grade D")} -> Grade B | P13: =INDEX($T$13:$W$15,MATCH(N13,$S$13:$S$15,0),MATCH(O13,$T$12:$W$12,0)) -> Low | S13: Mass Market | T13: Low | U13: Low | V13: Low | W13: Low
A14: 4849083 | B14: =TRIM('Raw Dataset'!B14) -> Eka Wijaya | C14: 16 | D14: Perempuan | E14: 44436 | F14: 695274 | G14: 44446 | H14: 621 | I14: 9144128 | J14: 23156763 | K14: SND03 | L14: =_xlfn.XLOOKUP(K14,Lookup!$G$4:$G$15,Lookup!$F$4:$F$15,"Unmapping",0,1) -> Jawa Tengah | M14: =VLOOKUP(H14,Lookup!$C$4:$D$9,2,0) -> Tab Hajj | N14: =IF(I14<10000000,"Mass Market",IF(I14<=50000000,"Optimal","Privilage")) -> Mass Market | O14: {=_xlfn.IFS(C14<=25,"Grade C",C14<=35,"Grade A",C14<=55,"Grade B",C14>55,"Grade D")} -> Grade C | P14: =INDEX($T$13:$W$15,MATCH(N14,$S$13:$S$15,0),MATCH(O14,$T$12:$W$12,0)) -> Low | S14: Optimal | T14: High | U14: High | V14: Middle | W14: Middle
A15: 5113873 | B15: =TRIM('Raw Dataset'!B15) -> Putri Kusuma | C15: 22 | D15: Perempuan | E15: 45700 | F15: 383843 | G15: 45710 | H15: 620 | I15: 14876013 | J15: 5558765 | K15: SND04 | L15: =_xlfn.XLOOKUP(K15,Lookup!$G$4:$G$15,Lookup!$F$4:$F$15,"Unmapping",0,1) -> Jawa Timur | M15: =VLOOKUP(H15,Lookup!$C$4:$D$9,2,0) -> Wadiah | N15: =IF(I15<10000000,"Mass Market",IF(I15<=50000000,"Optimal","Privilage")) -> Optimal | O15: {=_xlfn.IFS(C15<=25,"Grade C",C15<=35,"Grade A",C15<=55,"Grade B",C15>55,"Grade D")} -> Grade C | P15: =INDEX($T$13:$W$15,MATCH(N15,$S$13:$S$15,0),MATCH(O15,$T$12:$W$12,0)) -> Middle | S15: Privilage | T15: High | U15: High | V15: High | W15: High
A16: 5881429 | B16: =TRIM('Raw Dataset'!B16) -> Hendra Kusuma | C16: 62 | D16: Perempuan | E16: 43992 | F16: 970687 | G16: 44002 | H16: 521 | I16: 17183899 | J16: 24492905 | K16: SND05 | L16: =_xlfn.XLOOKUP(K16,Lookup!$G$4:$G$15,Lookup!$F$4:$F$15,"Unmapping",0,1) -> Kalimantan | M16: =VLOOKUP(H16,Lookup!$C$4:$D$9,2,0) -> Special Hajj | N16: =IF(I16<10000000,"Mass Market",IF(I16<=50000000,"Optimal","Privilage")) -> Optimal | O16: {=_xlfn.IFS(C16<=25,"Grade C",C16<=35,"Grade A",C16<=55,"Grade B",C16>55,"Grade D")} -> Grade D | P16: =INDEX($T$13:$W$15,MATCH(N16,$S$13:$S$15,0),MATCH(O16,$T$12:$W$12,0)) -> Middle
A17: 8573274 | B17: =TRIM('Raw Dataset'!B17) -> Indah Kurniawan | C17: 57 | D17: Perempuan | E17: 45255 | F17: 819522 | G17: 45265 | H17: 808 | I17: 14642960 | J17: 28520880 | K17: SND06 | L17: =_xlfn.XLOOKUP(K17,Lookup!$G$4:$G$15,Lookup!$F$4:$F$15,"Unmapping",0,1) -> Sumatera Utara | M17: =VLOOKUP(H17,Lookup!$C$4:$D$9,2,0) -> Tab Umroh | N17: =IF(I17<10000000,"Mass Market",IF(I17<=50000000,"Optimal","Privilage")) -> Optimal | O17: {=_xlfn.IFS(C17<=25,"Grade C",C17<=35,"Grade A",C17<=55,"Grade B",C17>55,"Grade D")} -> Grade D | P17: =INDEX($T$13:$W$15,MATCH(N17,$S$13:$S$15,0),MATCH(O17,$T$12:$W$12,0)) -> Middle
A18: 6265976 | B18: =TRIM('Raw Dataset'!B18) -> Fitri Susanti | C18: 21 | D18: Perempuan | E18: 43874 | F18: 408181 | G18: 43884 | H18: 413 | I18: 13499694 | J18: 18546605 | K18: SND01 | L18: =_xlfn.XLOOKUP(K18,Lookup!$G$4:$G$15,Lookup!$F$4:$F$15,"Unmapping",0,1) -> Jawa Barat | M18: =VLOOKUP(H18,Lookup!$C$4:$D$9,2,0) -> Tab Valas | N18: =IF(I18<10000000,"Mass Market",IF(I18<=50000000,"Optimal","Privilage")) -> Optimal | O18: {=_xlfn.IFS(C18<=25,"Grade C",C18<=35,"Grade A",C18<=55,"Grade B",C18>55,"Grade D")} -> Grade C | P18: =INDEX($T$13:$W$15,MATCH(N18,$S$13:$S$15,0),MATCH(O18,$T$12:$W$12,0)) -> Middle
A19: 2288253 | B19: =TRIM('Raw Dataset'!B19) -> Erna Hidayat | C19: 30 | D19: Perempuan | E19: 44317 | F19: 559401 | G19: 44327 | H19: 712 | I19: 18915499 | J19: 11478093 | K19: SND02 | L19: =_xlfn.XLOOKUP(K19,Lookup!$G$4:$G$15,Lookup!$F$4:$F$15,"Unmapping",0,1) -> Sumatera Selatan | M19: =VLOOKUP(H19,Lookup!$C$4:$D$9,2,0) -> Tab Syariah | N19: =IF(I19<10000000,"Mass Market",IF(I19<=50000000,"Optimal","Privilage")) -> Optimal | O19: {=_xlfn.IFS(C19<=25,"Grade C",C19<=35,"Grade A",C19<=55,"Grade B",C19>55,"Grade D")} -> Grade A | P19: =INDEX($T$13:$W$15,MATCH(N19,$S$13:$S$15,0),MATCH(O19,$T$12:$W$12,0)) -> High
A20: 8078818 | B20: =TRIM('Raw Dataset'!B20) -> Hadi Halim | C20: 58 | D20: Laki-laki | E20: 44924 | F20: 740849 | G20: 44934 | H20: 621 | I20: 13447101 | J20: 29853111 | K20: SND03 | L20: =_xlfn.XLOOKUP(K20,Lookup!$G$4:$G$15,Lookup!$F$4:$F$15,"Unmapping",0,1) -> Jawa Tengah | M20: =VLOOKUP(H20,Lookup!$C$4:$D$9,2,0) -> Tab Hajj | N20: =IF(I20<10000000,"Mass Market",IF(I20<=50000000,"Optimal","Privilage")) -> Optimal | O20: {=_xlfn.IFS(C20<=25,"Grade C",C20<=35,"Grade A",C20<=55,"Grade B",C20>55,"Grade D")} -> Grade D | P20: =INDEX($T$13:$W$15,MATCH(N20,$S$13:$S$15,0),MATCH(O20,$T$12:$W$12,0)) -> Middle
A21: 6068619 | B21: =TRIM('Raw Dataset'!B21) -> Gilang Kurniawan | C21: 62 | D21: Laki-laki | E21: 45378 | F21: 464201 | G21: 45388 | H21: 620 | I21: 15451751 | J21: 21605243 | K21: SND04 | L21: =_xlfn.XLOOKUP(K21,Lookup!$G$4:$G$15,Lookup!$F$4:$F$15,"Unmapping",0,1) -> Jawa Timur | M21: =VLOOKUP(H21,Lookup!$C$4:$D$9,2,0) -> Wadiah | N21: =IF(I21<10000000,"Mass Market",IF(I21<=50000000,"Optimal","Privilage")) -> Optimal | O21: {=_xlfn.IFS(C21<=25,"Grade C",C21<=35,"Grade A",C21<=55,"Grade B",C21>55,"Grade D")} -> Grade D | P21: =INDEX($T$13:$W$15,MATCH(N21,$S$13:$S$15,0),MATCH(O21,$T$12:$W$12,0)) -> Middle
A22: 2805431 | B22: =TRIM('Raw Dataset'!B22) -> Putri Nugroho | C22: 29 | D22: Laki-laki | E22: 44853 | F22: 557100 | G22: 44863 | H22: 521 | I22: 17245926 | J22: 9790888 | K22: SND05 | L22: =_xlfn.XLOOKUP(K22,Lookup!$G$4:$G$15,Lookup!$F$4:$F$15,"Unmapping",0,1) -> Kalimantan | M22: =VLOOKUP(H22,Lookup!$C$4:$D$9,2,0) -> Special Hajj | N22: =IF(I22<10000000,"Mass Market",IF(I22<=50000000,"Optimal","Privilage")) -> Optimal | O22: {=_xlfn.IFS(C22<=25,"Grade C",C22<=35,"Grade A",C22<=55,"Grade B",C22>55,"Grade D")} -> Grade A | P22: =INDEX($T$13:$W$15,MATCH(N22,$S$13:$S$15,0),MATCH(O22,$T$12:$W$12,0)) -> High
A23: 7107439 | B23: =TRIM('Raw Dataset'!B23) -> Yudi Lestari | C23: 54 | D23: Laki-laki | E23: 44769 | F23: 855954 | G23: 44779 | H23: 808 | I23: 12700508 | J23: 28045783 | K23: SND06 | L23: =_xlfn.XLOOKUP(K23,Lookup!$G$4:$G$15,Lookup!$F$4:$F$15,"Unmapping",0,1) -> Sumatera Utara | M23: =VLOOKUP(H23,Lookup!$C$4:$D$9,2,0) -> Tab Umroh | N23: =IF(I23<10000000,"Mass Market",IF(I23<=50000000,"Optimal","Privilage")) -> Optimal | O23: {=_xlfn.IFS(C23<=25,"Grade C",C23<=35,"Grade A",C23<=55,"Grade B",C23>55,"Grade D")} -> Grade B | P23: =INDEX($T$13:$W$15,MATCH(N23,$S$13:$S$15,0),MATCH(O23,$T$12:$W$12,0)) -> High
A24: 2991283 | B24: =TRIM('Raw Dataset'!B24) -> Putri Putra | C24: 45 | D24: Laki-laki | E24: 45681 | F24: 303911 | G24: 45691 | H24: 413 | I24: 5611240 | J24: 26907957 | K24: SND07 | L24: =_xlfn.XLOOKUP(K24,Lookup!$G$4:$G$15,Lookup!$F$4:$F$15,"Unmapping",0,1) -> DKI Jakarta | M24: =VLOOKUP(H24,Lookup!$C$4:$D$9,2,0) -> Tab Valas | N24: =IF(I24<10000000,"Mass Market",IF(I24<=50000000,"Optimal","Privilage")) -> Mass Market | O24: {=_xlfn.IFS(C24<=25,"Grade C",C24<=35,"Grade A",C24<=55,"Grade B",C24>55,"Grade D")} -> Grade B | P24: =INDEX($T$13:$W$15,MATCH(N24,$S$13:$S$15,0),MATCH(O24,$T$12:$W$12,0)) -> Low
A25: 4064701 | B25: =TRIM('Raw Dataset'!B25) -> Yudi Handoko | C25: 17 | D25: Laki-laki | E25: 45480 | F25: 222431 | G25: 45490 | H25: 712 | I25: 15009149 | J25: 18837109 | K25: SND08 | L25: =_xlfn.XLOOKUP(K25,Lookup!$G$4:$G$15,Lookup!$F$4:$F$15,"Unmapping",0,1) -> Papua | M25: =VLOOKUP(H25,Lookup!$C$4:$D$9,2,0) -> Tab Syariah | N25: =IF(I25<10000000,"Mass Market",IF(I25<=50000000,"Optimal","Privilage")) -> Optimal | O25: {=_xlfn.IFS(C25<=25,"Grade C",C25<=35,"Grade A",C25<=55,"Grade B",C25>55,"Grade D")} -> Grade C | P25: =INDEX($T$13:$W$15,MATCH(N25,$S$13:$S$15,0),MATCH(O25,$T$12:$W$12,0)) -> Middle
A26: 4135053 | B26: =TRIM('Raw Dataset'!B26) -> Citra Susanto | C26: 32 | D26: Laki-laki | E26: 44610 | F26: 929239 | G26: 44620 | H26: 621 | I26: 18567258 | J26: 21454990 | K26: SND09 | L26: =_xlfn.XLOOKUP(K26,Lookup!$G$4:$G$15,Lookup!$F$4:$F$15,"Unmapping",0,1) -> Bali | M26: =VLOOKUP(H26,Lookup!$C$4:$D$9,2,0) -> Tab Hajj | N26: =IF(I26<10000000,"Mass Market",IF(I26<=50000000,"Optimal","Privilage")) -> Optimal | O26: {=_xlfn.IFS(C26<=25,"Grade C",C26<=35,"Grade A",C26<=55,"Grade B",C26>55,"Grade D")} -> Grade A | P26: =INDEX($T$13:$W$15,MATCH(N26,$S$13:$S$15,0),MATCH(O26,$T$12:$W$12,0)) -> High
A27: 6257928 | B27: =TRIM('Raw Dataset'!B27) -> Chandra Saputra | C27: 34 | D27: Perempuan | E27: 44507 | F27: 477653 | G27: 44517 | H27: 620 | I27: 19789506 | J27: 13204992 | K27: SND10 | L27: =_xlfn.XLOOKUP(K27,Lookup!$G$4:$G$15,Lookup!$F$4:$F$15,"Unmapping",0,1) -> Maluku | M27: =VLOOKUP(H27,Lookup!$C$4:$D$9,2,0) -> Wadiah | N27: =IF(I27<10000000,"Mass Market",IF(I27<=50000000,"Optimal","Privilage")) -> Optimal | O27: {=_xlfn.IFS(C27<=25,"Grade C",C27<=35,"Grade A",C27<=55,"Grade B",C27>55,"Grade D")} -> Grade A | P27: =INDEX($T$13:$W$15,MATCH(N27,$S$13:$S$15,0),MATCH(O27,$T$12:$W$12,0)) -> High
... A135: 5113873 | B135: =TRIM('Raw Dataset'!B135) -> Putri Kusuma | C135: 22 | D135: Perempuan | E135: 45700 | F135: 383843 | G135: 45710 | H135: 620 | I135: 14876013 | J135: 5558765 | K135: SND04 | L135: =_xlfn.XLOOKUP(K135,Lookup!$G$4:$G$15,Lookup!$F$4:$F$15,"Unmapping",0,1) -> Jawa Timur | M135: =VLOOKUP(H135,Lookup!$C$4:$D$9,2,0) -> Wadiah | N135: =IF(I135<10000000,"Mass Market",IF(I135<=50000000,"Optimal","Privilage")) -> Optimal | O135: {=_xlfn.IFS(C135<=25,"Grade C",C135<=35,"Grade A",C135<=55,"Grade B",C135>55,"Grade D")} -> Grade C | P135: =INDEX($T$13:$W$15,MATCH(N135,$S$13:$S$15,0),MATCH(O135,$T$12:$W$12,0)) -> Middle

Sheet Lookup
C3: Code | D3: Product Name | F3: Name | G3: Region | I3: Cust Segmen | J3: Tier Prioritas
C4: 621 | D4: Tab Hajj | F4: Jawa Barat | G4: SND01 | J4: Grade A | K4: Grade B | L4: Grade C | M4: Grade D
C5: 620 | D5: Wadiah | F5: Sumatera Selatan | G5: SND02 | I5: Mass Market | J5: Low | K5: Low | L5: Low | M5: Low
C6: 521 | D6: Special Hajj | F6: Jawa Tengah | G6: SND03 | I6: Optimal | J6: High | K6: High | L6: Middle | M6: Middle
C7: 808 | D7: Tab Umroh | F7: Jawa Timur | G7: SND04 | I7: Privilege | J7: High | K7: High | L7: High | M7: High
C8: 413 | D8: Tab Valas | F8: Kalimantan | G8: SND05
C9: 712 | D9: Tab Syariah | F9: Sumatera Utara | G9: SND06 | I9: Segment | J9: Balance | L9: Tier | M9: Usia
F10: DKI Jakarta | G10: SND07 | I10: Mass Market | J10: < 10 Juta | L10: Grade A | M10: 25-35
F11: Papua | G11: SND08 | I11: Optimal | J11: 10-50 Juta | L11: Grade B | M11: 35-55
F12: Bali | G12: SND09 | I12: Privilege | J12: > 50 Juta | L12: Grade C | M12: < 25
F13: Maluku | G13: SND10 | L13: Grade D | M13: > 55
F14: Sulawesi Utara | G14: SND11
F15: Sulawesi Tenggara | G15: SND12

Sheet Pivot Table
A3: Count of Flag | B3: Column Labels
A4: Row Labels | B4: High | C4: Low | D4: Middle | E4: Grand Total
A5: Grade A | B5: 14 | C5: 17 | E5: 31
A6: Grade B | B6: 23 | C6: 23 | E6: 46
A7: Grade C | B7: 13 | C7: 13 | D7: 9 | E7: 35
A8: Grade D | B8: 8 | C8: 7 | D8: 7 | E8: 22
A9: Grand Total | B9: 58 | C9: 60 | D9: 16 | E9: 134

Sheet Chart
B2: *Summary Data
B4: Region | C4: Total Customer | D4: Sum of Balance | E4: Average of Balance
B5: Jawa Barat | C5: 22 | D5: 1159201312 | E5: 52870320
B6: Sumatera Selatan | C6: 14 | D6: 658257282 | E6: 49933059
B7: Sulawesi Tenggara | C7: 20 | D7: 449105756 | E7: 24103530
B8: Jawa Timur | C8: 14 | D8: 308532464 | E8: 18918210
B9: Jawa Tengah | C9: 12 | D9: 233389404 | E9: 25430953
B10: Sumatera Utara | C10: 9 | D10: 172508317 | E10: 23298641
B11: Kalimantan | C11: 9 | D11: 164387292 | E11: 14124271
B12: Maluku | C12: 6 | D12: 149634306 | E12: 21777747
B13: Bali | C13: 6 | D13: 134812268 | E13: 22915962
B14: Sulawesi Utara | C14: 6 | D14: 121731484 | E14: 28589341
B15: DKI Jakarta | C15: 7 | D15: 119907363 | E15: 16540912
B16: Papua | C16: 9 | D16: 89174366 | E16: 12836764
B17: Grand Total | C17: =SUM(C5:C16) -> 134 | D17: =SUM(D5:D16) -> 3760641614 | E17: =SUM(E5:E16) -> 3.1133971e+08
B19: *Total Customer & Balance by Segment
B21: Segment | C21: Total Customer | D21: Total Balance
B22: Mass Market | C22: 60 | D22: 293852589
B23: Privilege | C23: 39 | D23: 2919740465
B24: Optimal | C24: 35 | D24: 547048560
B25: Grand Total | C25: 134 | D25: 3760641614
B34: *Customer by Age Grade
B36: Customer Profiling | C36: Total Customer
B37: Grade A | C37: 31
B38: Grade B | C38: 46
B39: Grade C | C39: 35
B40: Grade D | C40: 22
B41: Grand Total | C41: 134
B49: *Product Distribution
B51: Product Name | C51: Gender | E51: Total
C52: Male | D52: Female
B53: Tab Syariah | C53: 32 | D53: 21 | E53: 53
B54: Wadiah | C54: 12 | D54: 10 | E54: 22
B55: Tab Hajj | C55: 5 | D55: 12 | E55: 17
B56: Special Hajj | C56: 6 | D56: 10 | E56: 16
B57: Tab Umroh | C57: 3 | D57: 10 | E57: 13
B58: Tab Valas | C58: 9 | D58: 4 | E58: 13
B59: Grand Total | C59: 67 | D59: 67 | E59: 134
B65: *Priority Leads by Region
B67: Region | C67: Tier Priority | F67: Total
...

Sheet DASHBOARD
C3: CUSTOMER LEADS POTENTIAL ANALYSIS DASHBOARD
C5: I. Summary Performance
D7: Total Customer | E7: Total Balance | F7: Average Balance | G7: Total High Priority Customer
D8: 134 | E8: 3760641614 | F8: 3.1133971e+08 | G8: 58
C11: II. Customer Analysis

Sheet KEY FINDINGS
C3: KEY FINDINGS
C7: ● | E7: The majority of customers are concentrated in the Mass Market segment.
C9: ● | E9: The Privilege segment contributes the highest total balance with balance 2,919,740,465, indicating a higher
E10: funding contribution from this customer group.
C12: ● | E12: Grade B represents the largest customer group, accounting for 34% of the total customer population based on
E13: age classification.
C15: ● | E15: High-priority customers are mainly concentrated in the Jawa Barat region, indicating a potential target area for
E16: marketing activities.
C18: ● | E18: The combination of customer segment and age grade identifies B customers as High Priority, representing
E19: the most potential target for marketing
